Workbook

Sheet Cover
D14: Typ dokumentu | F14: Plik z danymi roku bazowego
D18: Cel powstania | F18: Wprowadzenie topologii i danych dla sektora rolnictwa
D22: Data powstania | F22: 45173
D25: Ostatnia aktualizacja | F25: 45915
D28: Autor(zy) | F28: Artur Wyrwa
F29: Patrycja Rzeszut
F30: Maciej Raczyński
F31: Janusz Zyśk
D33: Osoba kontaktowa | F33: Artur Wyrwa
F34: awyrwa@agh.edu.pl

Sheet Metadane
D4: Metadane
D6: Wersja modelu wykorzystująca plik: TIMES-PL
D8: Arkusz | E8: Moduł | F8: Uwagi
D9: AGR_Comm | E9: Bazowy | F9: Zaktualizowano listę dóbr
D10: AGR_Proc | E10: Bazowy | F10: Zaktualizowano listę procesów
D11: SECTF | E11: Bazowy | F11: Zaktualizowano listę procesów i dóbr
D12: AGR_LIV | E12: TIMES-PL Rozszerzenie
D13: AGR_LAND | E13: TIMES-PL Rozszerzenie
D14: AGR_BIOG | E14: TIMES-PL Rozszerzenie
D15: AGR_CHP | E15: Bazowy
D16: DIV | E16: TIMES-PL Rozszerzenie
D17: AGR_FEC | E17: Bazowy
D18: EMI | E18: Bazowy | F18: Zaktualizowano listę procesów i dóbr

Sheet AGR_Comm
B2: Definicja dóbr | Commodity Definition
B4: ~FI_Comm
B5: Csets | C5: Region | D5: CommName | E5: CommDesc | F5: Unit | G5: LimType | H5: CTSLvl | I5: PeakTS | J5: Ctype
B6: * Przynależność do zbioru dóbr | C6: Region | D6: Nazwa dobra | E6: Opis dobra | F6: Jednostka | G6: Znak w równaniu bilansu | H6: Poziom podokresów | I6: Monitorowanie szczytu | J6: Wskaźnik energii elektrycznej
B7: NRG | C7: PL | D7: AGR_HC | E7: Hard Coal | F7: PJ | H7: ANNUAL
B8: NRG | C8: PL | D8: AGR_BC | E8: Brown Coal | F8: PJ | H8: ANNUAL
B9: NRG | C9: PL | D9: AGR_OIL_GSL | E9: Gasoline | F9: PJ | H9: ANNUAL
B10: NRG | C10: PL | D10: AGR_OIL_DSL | E10: Diesel | F10: PJ | H10: ANNUAL
B11: NRG | C11: PL | D11: AGR_OIL_LPG | E11: LPG | F11: PJ | H11: ANNUAL
B12: NRG | C12: PL | D12: AGR_OIL_FUE | E12: Fuel Oil | F12: PJ | H12: ANNUAL
B13: NRG | C13: PL | D13: AGR_NAT_GAS | E13: Natural Gas | F13: PJ | H13: ANNUAL
B14: NRG | C14: PL | D14: PRI_BIOG_AGR | E14: Biogas AGR | F14: PJ | H14: ANNUAL
B15: NRG | C15: PL | D15: PRI_BIO_CH4_AGR | E15: Biometan AGR | F15: PJ | H15: ANNUAL
B16: NRG | C16: PL | D16: AGR_BIOG | E16: Biogas AGR | F16: PJ | H16: ANNUAL
B17: NRG | C17: PL | D17: AGR_BIOM | E17: Biomass | F17: PJ | H17: ANNUAL
B18: NRG | C18: PL | D18: AGR_RDF | E18: RDF | F18: PJ | H18: ANNUAL
... B22: DEM | C22: PL | D22: AGR_DEM | E22: Agriculture Demand | F22: IPI | H22: ANNUAL
B23: ENV | C23: PL | D23: AGR_CO2 | E23: Carbon Dioxide - Combustion (AGR) | F23: kt
B24: ENV | C24: PL | D24: AGR_SO2 | E24: Sulphur Dioxide - Combustion (AGR) | F24: kt
B25: ENV | C25: PL | D25: AGR_NOX | E25: Nitrogen Oxides - Combustion (AGR) | F25: kt
B26: ENV | C26: PL | D26: AGR_TSP | E26: Total Suspended Particulate - Combustion (AGR)
B27: ENV | C27: PL | D27: AGR_PM10 | E27: Particulate Matter <= 10 um - Combustion (AGR) | F27: kt
B28: ENV | C28: PL | D28: AGR_PM2.5 | E28: Particulate Matter <= 2.5 um - Combustion (AGR) | F28: kt
B29: ENV | C29: PL | D29: AGR_HG | E29: Mercury - Combustion (AGR) | F29: kt
B30: \I: NRG | C30: PL | D30: HT_AGR_CHPI | F30: PJ | H30: DAYNITE
B31: NRG | C31: PL | D31: AGR_HT_OWN_USE | F31: PJ | H31: ANNUAL
B32: \I: nowododane dobra dla biogazowni
B33: \I: NRG | C33: PL | D33: AGR_BIO_CH4 | E33: Agricultural Biomethane | F33: PJ
B34: ENV | C34: PL | D34: AGR_N2O | E34: Nitrous Oxide - Field (AGR) | F34: kt
B35: ENV | C35: PL | D35: AGR_CH4_ENT | E35: Methane - Livestock Enteric Digestion (AGR) | F35: kt
B36: ENV | C36: PL | D36: AGR_CH4_MAN | E36: Methane - Livestock Manure (AGR) | F36: kt
B37: \I: ENV | C37: PL | D37: AGR_CH4_LAND | E37: Methane - LAND (AGR) | F37: kt
B38: NRG | C38: PL | D38: AGR_LIV_MANURE_CAT_DAIRY | E38: Animal Manure - Dairy Cattle | F38: kt
B39: NRG | C39: PL | D39: AGR_LIV_MANURE_CAT_NON-DAIRY | E39: Animal Manure - Non Dairy Cattle | F39: kt
B40: NRG | C40: PL | D40: AGR_LIV_MANURE_SHEEP | E40: Animal Manure - Sheep | F40: kt
B41: NRG | C41: PL | D41: AGR_LIV_MANURE_SWINE | E41: Animal Manure - Swine | F41: kt
B42: NRG | C42: PL | D42: AGR_LIV_MANURE_GOAT | E42: Animal Manure - Goat | F42: kt
B43: \I: | C43: PL | D43: AGR_LIV_MANURE_HORSE | E43: Animal Manure - Horse | F43: kt
B44: NRG | C44: PL | D44: AGR_LIV_MANURE_POULTRY | E44: Animal Manure - Poultry | F44: kt
... B61: NRG | C61: PL | D61: AGR_RESID_CROP_VEG | E61: Crop Residues | F61: kt
...

Sheet AGR_Proc
B2: Definicja procesów | Process Definition
B4: ~FI_Process
B5: Sets | C5: Region | D5: TechName | E5: TechDesc | F5: Tact | G5: Tcap | H5: Tslvl | I5: PrimaryCG | J5: Vintage
B6: * Przynależność do zbioru procesów | C6: Nazwa regionu | D6: Nazwa technologii | E6: Opis technologii | F6: Jednostka aktywności | G6: Jednostka mocy | H6: Podokres aktywności procesu | I6: Przynależność do grupy głównej dóbr | J6: Śledzenie rocznika
B7: PRE | C7: PL | D7: SECTF_AGR_HC | E7: Sector fuel - Hard Coal | F7: PJ | G7: Pja
B8: PRE | C8: PL | D8: SECTF_AGR_BC | E8: Sector fuel - Brown Coal | F8: PJ | G8: Pja
B9: PRE | C9: PL | D9: SECTF_AGR_OIL_GSL | E9: Sector fuel - Gasoline | F9: PJ | G9: Pja
B10: PRE | C10: PL | D10: SECTF_AGR_OIL_DSL | E10: Sector fuel - Diesel | F10: PJ | G10: Pja
B11: PRE | C11: PL | D11: SECTF_AGR_OIL_LPG | E11: Sector fuel - LPG | F11: PJ | G11: Pja
B12: PRE | C12: PL | D12: SECTF_AGR_OIL_FUE | E12: Sector fuel - Fuel Oil | F12: PJ | G12: Pja
B13: PRE | C13: PL | D13: SECTF_AGR_NAT_GAS | E13: Sector fuel - Natural Gas | F13: PJ | G13: Pja
B14: PRE | C14: PL | D14: SECTF_AGR_BIOG | E14: Sector fuel - Biogas | F14: PJ | G14: Pja
B15: PRE | C15: PL | D15: SECTF_AGR_BIOM | E15: Sector fuel - Biomass | F15: PJ | G15: Pja
B16: PRE | C16: PL | D16: SECTF_AGR_RDF | E16: Sector fuel - RDF | F16: PJ | G16: Pja
B17: PRE | C17: PL | D17: SECTF_AGR_ELC | E17: Sector fuel - Electricity | F17: PJ | G17: Pja | H17: DAYNITE
B18: PRE | C18: PL | D18: SECTF_AGR_DH | E18: Sector fuel - District Heat | F18: PJ | G18: Pja | H18: ANNUAL
B19: PRE | C19: PL | D19: SECTF_AGR_OTH | E19: Sector fuel - Other Fuels | F19: PJ | G19: Pja
B20: DMD | C20: PL | D20: AGR_DEM_OWN_HEAT | E20: Heat demand related to CHPs in agr., e.g. drying | F20: PJ | G20: Pja
B21: DMD | C21: PL | D21: AGR_DEM_AGR | E21: Agriculture Demand Process | F21: IPI | G21: IPIa
B22: CHP | C22: PL | D22: CHPI_EX_BIOG_AGR | E22: Industrial Chp Plants for biogas from agriculture residues | F22: PJ | G22: GW | H22: DAYNITE | J22: NO
B23: \I: | C23: PL | D23: ELC_VOLT_DIV_AGR_CHPI | E23: Voltage Divider - AGR CHPI | F23: PJ | G23: PJa | H23: DAYNITE
B24: \I: PRE | C24: PL | D24: HT_DIV_AGR_CHPI | E24: Heat Divider - AGR CHPI | F24: PJ | G24: PJa | H24: DAYNITE
B25: \I: nowododane procesy dla biogazu
B26: PRE | C26: PL | D26: AGR_EX_BIOG | E26: Agriculture Existing Biogass | F26: PJ | G26: mln m3 | H26: ANNUAL
B27: PRE | C27: PL | D27: AGR_EX_BIOG_CLEAN | E27: Agriculture Biogaz Cleaning | F27: PJ | G27: Pja | H27: ANNUAL
B28: \I: | C28: PL | D28: AGR_IMP_DUMMY_NRG_LIV | E28: Dummy Energy Import | F28: DUM | G28: DUM | H28: ANNUAL
B29: \I: | C29: PL | D29: AGR_IMP_LAND_RESIDUE | E29: Dummy Import of Crop Residues for Biogas Production | F29: kt | G29: kt | H29: ANNUAL
B30: \I: | C30: PL | D30: AGR_IMP_DUMMY_NRG_LAND | E30: Dummy Land Import | F30: DUM | G30: DUM | H30: ANNUAL
B31: IMP | C31: PL | D31: AGR_IMP_DUMMY_FOOD_LIV | E31: Dummy Energy Import | F31: IPI | G31: 1000s of animals | H31: ANNUAL
B32: IMP | C32: PL | D32: AGR_IMP_DUMMY_LAND | E32: Dummy Land Import | F32: kha/a | G32: kha | H32: ANNUAL
B33: PRE | C33: PL | D33: AGR_EX_LIV_CAT_DAIRY | E33: AGR_LIV_CAT_DAIRY | F33: IPI | G33: 1000s of animals | H33: ANNUAL
B34: PRE | C34: PL | D34: AGR_EX_LIV_CAT_NON-DAIRY | E34: AGR_LIV_CAT_NON-DAIRY | F34: IPI | G34: 1000s of animals | H34: ANNUAL
B35: PRE | C35: PL | D35: AGR_EX_LIV_SHEEP | E35: AGR_LIV_SHEEP | F35: IPI | G35: 1000s of animals | H35: ANNUAL
B36: PRE | C36: PL | D36: AGR_EX_LIV_SWINE | E36: AGR_LIV_SWINE | F36: IPI | G36: 1000s of animals | H36: ANNUAL
B37: PRE | C37: PL | D37: AGR_EX_LIV_GOAT | E37: AGR_LIV_GOAT | F37: IPI | G37: 1000s of animals | H37: ANNUAL
... B71: \I:IMP | C71: PL | D71: AGR_IMP_LAND_RESIDUE | E71: Dummy Import of Crop Residues for Biogas Production | F71: kt | G71: kt | H71: ANNUAL
B72: PRE | C72: PL | D72: AGR_PRC_MECH_WORK | F72: PJ | G72: PJa | H72: ANNUAL
B73: PRE | C73: PL | D73: AGR_PRC_DRY_SVC | F73: PJ | G73: PJa | H73: ANNUAL
B74: PRE | C74: PL | D74: AGR_PRC_LIV_HT | F74: PJ | G74: PJa | H74: ANNUAL
B75: PRE | C75: PL | D75: AGR_PRC_LIV_ELC_SVC | F75: PJ | G75: PJa | H75: ANNUAL
...

Sheet SECTF
B2: Paliwa sektorowe | Sector fuels
E4: ~FI_T: PL
B5: TechName | C5: * TechDesc | D5: Comm-IN | E5: Comm-OUT | F5: EFF | G5: Share-I~UP | H5: Share-I~UP~0 | I5: FLO_COST~2020~2021 | J5: FLO_COST~2025 | K5: FLO_COST~2030 | L5: FLO_COST~2035 | M5: FLO_COST~2040 | N5: FLO_COST~2045 | O5: FLO_COST~2050 | P5: FLO_DELIV~2020~2021 | Q5: FLO_DELIV~2025 | R5: FLO_DELIV~2030 | S5: FLO_DELIV~2035 | T5: FLO_DELIV~2040 | U5: FLO_DELIV~2045 | V5: FLO_DELIV~2050 | W5: FLO_TAX
B6: \I: UNITS | I6: Mzl/PJ | J6: Mzl/PJ | K6: Mzl/PJ | L6: Mzl/PJ | M6: Mzl/PJ | N6: Mzl/PJ | O6: Mzl/PJ | P6: Mzl/PJ | Q6: Mzl/PJ | R6: Mzl/PJ | S6: Mzl/PJ | T6: Mzl/PJ | U6: Mzl/PJ | V6: Mzl/PJ | W6: Mzl/PJ
B7: =AGR_Proc!D7 -> SECTF_AGR_HC | C7: =AGR_Proc!E7 -> Sector fuel - Hard Coal | D7: PRI_HC | F7: 1
E8: =AGR_Comm!D7 -> AGR_HC | P8: 7.81 | Q8: 12 | R8: 12 | S8: 12 | T8: 12 | U8: 12 | V8: 12
B9: =AGR_Proc!D8 -> SECTF_AGR_BC | C9: =AGR_Proc!E8 -> Sector fuel - Brown Coal | D9: PRI_BC | F9: 1
E10: =AGR_Comm!D8 -> AGR_BC
B11: =AGR_Proc!D9 -> SECTF_AGR_OIL_GSL | C11: =AGR_Proc!E9 -> Sector fuel - Gasoline | D11: SEC_OIL_GSL | F11: 1
E12: =AGR_Comm!D9 -> AGR_OIL_GSL
B13: =AGR_Proc!D10 -> SECTF_AGR_OIL_DSL | C13: =AGR_Proc!E10 -> Sector fuel - Diesel | D13: SEC_OIL_DSL | F13: 1
E14: =AGR_Comm!D10 -> AGR_OIL_DSL
B15: =AGR_Proc!D11 -> SECTF_AGR_OIL_LPG | C15: =AGR_Proc!E11 -> Sector fuel - LPG | D15: SEC_OIL_LPG | F15: 1
E16: =AGR_Comm!D11 -> AGR_OIL_LPG
B17: =AGR_Proc!D12 -> SECTF_AGR_OIL_FUE | C17: =AGR_Proc!E12 -> Sector fuel - Fuel Oil | D17: SEC_OIL_FUE | F17: 1
E18: =AGR_Comm!D12 -> AGR_OIL_FUE
B19: =AGR_Proc!D13 -> SECTF_AGR_NAT_GAS | C19: =AGR_Proc!E13 -> Sector fuel - Natural Gas | D19: PRI_GAS_NAT_LP | F19: 1 | I19: 2.25 | J19: 5.04 | K19: =J19 -> 5.04 | L19: =K19 -> 5.04 | M19: =L19 -> 5.04 | N19: =M19 -> 5.04 | O19: =N19 -> 5.04
E20: =AGR_Comm!D13 -> AGR_NAT_GAS | P20: 6.19 | Q20: 7.44 | R20: =Q20 -> 7.44 | S20: =R20 -> 7.44 | T20: =S20 -> 7.44 | U20: =T20 -> 7.44 | V20: =U20 -> 7.44
B21: =AGR_Proc!D14 -> SECTF_AGR_BIOG | C21: =AGR_Proc!E14 -> Sector fuel - Biogas | D21: PRI_BIOG_AGR | F21: 1 | Y21: =AGR_Proc!D14 -> SECTF_AGR_BIOG | AA21: Biogaz rolniczy wytwarza się sam
E22: =OLD_AGR_Comm!D14 -> AGR_BIOG
B23: =AGR_Proc!D15 -> SECTF_AGR_BIOM | C23: =AGR_Proc!E15 -> Sector fuel - Biomass | D23: PRI_BIO_WOOD | F23: 1
E24: =AGR_Comm!D17 -> AGR_BIOM
B25: =AGR_Proc!D16 -> SECTF_AGR_RDF | C25: =AGR_Proc!E16 -> Sector fuel - RDF | D25: PRI_NREN_RDF | F25: 1
D26: PRI_REN_RDF
E27: =AGR_Comm!D18 -> AGR_RDF
B28: =AGR_Proc!D17 -> SECTF_AGR_ELC | C28: =AGR_Proc!E17 -> Sector fuel - Electricity | F28: 1
D29: ELC_LV-LV | G29: 0.91 | I29: 9.5112 | J29: 25 | K29: =J29 -> 25 | L29: =K29 -> 25 | M29: =L29 -> 25 | N29: =M29 -> 25 | O29: =N29 -> 25 | P29: 53.8966 | Q29: 141.68 | R29: =Q29 -> 141.68 | S29: =R29 -> 141.68 | T29: =S29 -> 141.68 | U29: =T29 -> 141.68 | V29: =U29 -> 141.68
E30: =AGR_Comm!D19 -> AGR_ELC
B31: =AGR_Proc!D18 -> SECTF_AGR_DH | C31: =AGR_Proc!E18 -> Sector fuel - District Heat | D31: HT_DH | F31: 1
E32: =AGR_Comm!D20 -> AGR_DH | P32: 19 | Q32: 25 | R32: =Q32 -> 25 | S32: =R32 -> 25 | T32: =S32 -> 25 | U32: =T32 -> 25 | V32: =U32 -> 25
B33: =AGR_Proc!D19 -> SECTF_AGR_OTH | C33: =AGR_Proc!E19 -> Sector fuel - Other Fuels | D33: PRI_IND_OTH_FUE | E33: =AGR_Comm!D21 -> AGR_OTH_FUE | F33: 1
G37: MV Jako możliwość

Sheet AGR_LAND
B4: TechName | C4: *TechDesc | D4: Comm-IN | E4: Comm-OUT | F4: Comm-OUT-A | G4: Stock~2020~2050 | H4: Output~2020~AGR_N2O | I4: Output~2050~AGR_N2O | J4: Cap2Act | K4: AFA~FX | L4: Input
B5: * Technology name | C5: Technology description | E5: Commodity output | G5: k ha | H5: kt/k ha
B6: AGR_FERT_N_INORG | C6: AGR_FERT_N_INORG | D6: AGR_LAND | E6: AGR_DUMMY_DMD_LAND | F6: AGR_N2O | G6: 100 | H6: 0.0033536446 | I6: 0.0033536446 | J6: 1 | K6: 1 | L6: 1
B7: AGR_FERT_N_MANURE | C7: AGR_FERT_N_MANURE | D7: AGR_LAND | E7: AGR_DUMMY_DMD_LAND | F7: AGR_N2O | G7: 100 | H7: 0.0013636722 | I7: 0.0013636722 | J7: 1 | K7: 1 | L7: 1
B8: AGR_FERT_N_SLUDGE | C8: AGR_FERT_N_SLUDGE | D8: AGR_LAND | E8: AGR_DUMMY_DMD_LAND | F8: AGR_N2O | G8: 100 | H8: 1.6167877e-05 | I8: 1.6167877e-05 | J8: 1 | K8: 1 | L8: 1
B9: AGR_FERT_N_URINE | C9: AGR_FERT_N_URINE | D9: AGR_LAND | E9: AGR_DUMMY_DMD_LAND | F9: AGR_N2O | G9: 100 | H9: 0.00035521266 | I9: 0.00035521266 | J9: 1 | K9: 1 | L9: 1
B10: AGR_FERT_N_CROP-RES | C10: AGR_FERT_N_CROP-RES | D10: AGR_LAND | E10: AGR_DUMMY_DMD_LAND | F10: AGR_N2O | G10: 100 | H10: 0.0013317293 | I10: 0.0013317293 | J10: 1 | K10: 1 | L10: 1
B11: AGR_FERT_N_MIN | C11: AGR_FERT_N_MIN | D11: AGR_LAND | E11: AGR_DUMMY_DMD_LAND | F11: AGR_N2O | G11: 100 | H11: 3.3444093e-05 | I11: 3.3444093e-05 | J11: 1 | K11: 1 | L11: 1
B12: AGR_FERT_N_CULT | C12: AGR_FERT_N_CULT | D12: AGR_LAND | E12: AGR_DUMMY_DMD_LAND | F12: AGR_N2O | G12: 100 | H12: 0.0023921301 | I12: 0.0023921301 | J12: 1 | K12: 1 | L12: 1
B13: AGR_FERT_N_ATM-DEP | C13: AGR_FERT_N_ATM-DEP | D13: AGR_LAND | E13: AGR_DUMMY_DMD_LAND | F13: AGR_N2O | G13: 100 | H13: 0.00064745988 | I13: 0.00064745988 | J13: 1 | K13: 1 | L13: 1
B14: AGR_FERT_N_NITR-LEACH | C14: AGR_FERT_N_NITR-LEACH | D14: AGR_LAND | E14: AGR_DUMMY_DMD_LAND | F14: AGR_N2O | G14: 100 | H14: 0.0014128414 | I14: 0.0014128414 | J14: 1 | K14: 1 | L14: 1
B17: TechName | C17: *TechDesc | D17: Comm-IN | E17: Comm-OUT | F17: Comm-OUT-A | G17: Stock~2020~2050 | H17: Output~2020~AGR_CO2 | I17: Output~2050~AGR_CO2 | J17: Cap2Act | K17: AFA~FX | L17: Input
B18: * Technology name | C18: Technology description | E18: Commodity output | G18: k ha | H18: kt/k ha
B19: AGR_LAND_FERT_CO2_LIM | C19: AGR_LAND_FERT_CO2_LIM | D19: AGR_LAND | E19: AGR_DUMMY_DMD_LAND | F19: AGR_CO2 | G19: 100 | H19: 0.13152132 | I19: 0.13152132 | J19: 1 | K19: 1 | L19: 1
B20: AGR_LAND_FERT_CO2_DOL | C20: AGR_LAND_FERT_CO2_DOL | D20: AGR_LAND | E20: AGR_DUMMY_DMD_LAND | F20: AGR_CO2 | G20: 100 | H20: 0.048130325 | I20: 0.048130325 | J20: 1 | K20: 1 | L20: 1
B21: AGR_LAND_FERT_CO2_UREA | C21: AGR_LAND_FERT_CO2_UREA | D21: AGR_LAND | E21: AGR_DUMMY_DMD_LAND | F21: AGR_CO2 | G21: 100 | H21: 0.089067159 | I21: 0.089067159 | J21: 1 | K21: 1 | L21: 1
B22: AGR_LAND_FERT_CO2_OTH | C22: AGR_LAND_FERT_CO2_OTH | D22: AGR_LAND | E22: AGR_DUMMY_DMD_LAND | F22: AGR_CO2 | G22: 100 | H22: 0.053429613 | I22: 0.053429613 | J22: 1 | K22: 1 | L22: 1
F25: ~FI_T:PL
B26: TechName | C26: *TechDesc | D26: Comm-IN | E26: Comm-OUT | F26: Comm-OUT-A | G26: Stock~2024 | H26: Stock~2025 | I26: Stock~2030 | J26: Stock~2035 | K26: Stock~2040 | L26: Stock~2045 | M26: Stock~2050 | N26: Input~2024 | O26: Input~2025 | P26: Input~2030 | Q26: Input~2035 | R26: Input~2040 | S26: Input~2045 | T26: Input~2050 | U26: Output~2024 | V26: Output~2025 | W26: Output~2030 | X26: Output~2035 | Y26: Output~2040 | Z26: Output~2045 | AA26: Output~2050 | AB26: Cap2Act | AC26: ACTFLO~2024 | AD26: ACTFLO~2025 | AE26: ACTFLO~2030 | AF26: ACTFLO~2035 | AG26: ACTFLO~2040 | AH26: ACTFLO~2045 | AI26: ACTFLO~2050 | AJ26: AFA | AK26: Output~2020~AGR_N2O | AL26: Output~2050~AGR_N2O | AN26: Uzysk odpadów 2024 | AO26: Uzysk odpadów 2025 | AP26: Uzysk odpadów 2030 | AQ26: Uzysk odpadów 2035 | AR26: Uzysk odpadów 2040 | AS26: Uzysk odpadów 2045 | AT26: Uzysk odpadów 2050 | AU26: Współczynnik zebrania | AW26: Produkcja odpadów max
B27: * Technology name | C27: Technology description | E27: Commodity output | G27: k ha | H27: k ha | I27: k ha | J27: k ha | K27: k ha | L27: k ha | M27: k ha | N27: kha/kha | U27: kt/kha | AC27: kt/kha | AD27: kt/kha | AE27: kt/kha | AF27: kt/kha | AG27: kt/kha | AH27: kt/kha | AI27: kt/kha | AK27: kt/k ha | AN27: t/ha | AO27: t/ha | AP27: t/ha | AQ27: t/ha | AR27: t/ha | AS27: t/ha | AT27: t/ha | AW27: kt
B28: AGR_LAND_CROP_WHEAT | C28: AGR_LAND_CROP_WHEAT | G28: =Y140 -> 2385.693 | H28: 2414.111 | I28: 2428.6907 | J28: 2190.4248 | K28: 1956.1429 | L28: 1725.7935 | M28: 1499.3258 | AB28: 1 | AJ28: 1
D29: =AGR_Comm!D63 -> AGR_LAND | N29: 1 | O29: 1 | P29: 1 | Q29: 1 | R29: 1 | S29: 1 | T29: 1
D30: =AGR_Comm!D93 -> AGR_MACH_WORK | N30: =AGR_SVC!N121 -> 0.0030442496 | O30: =AGR_SVC!AP121 -> 0.0030370705 | P30: =AGR_SVC!BD121 -> 0.0027741051 | Q30: =AGR_SVC!BR121 -> 0.0027980839 | R30: =AGR_SVC!CF121 -> 0.0028185575 | S30: =AGR_SVC!CT121 -> 0.0028338342 | T30: =AGR_SVC!AB121 -> 0.0028411038
D31: =AGR_Comm!D94 -> AGR_DRY_SVC | N31: =AGR_SVC!O121 -> 0.00051400711 | O31: =AGR_SVC!AQ121 -> 0.00050334749 | P31: =AGR_SVC!BE121 -> 0.00049311342 | Q31: =AGR_SVC!BS121 -> 0.00058586881 | R31: =AGR_SVC!CG121 -> 0.00071862313 | S31: =AGR_SVC!CU121 -> 0.00092434721 | T31: =AGR_SVC!AC121 -> 0.0012859811
D32: =AGR_Comm!D97 -> AGR_OTH_SVC | N32: =AGR_SVC!R121 -> 0.0013836154 | O32: =AGR_SVC!AT121 -> 0.001407374 | P32: =AGR_SVC!BH121 -> 0.001431353 | Q32: =AGR_SVC!BV121 -> 0.0016281797 | R32: =AGR_SVC!CJ121 -> 0.001875697 | S32: =AGR_SVC!CX121 -> 0.0021960249 | T32: =AGR_SVC!AF121 -> 0.0026263346
E33: AGR_DEM_CROP_WHEAT | AC33: =Z140/10 -> 5.2 | AD33: 5.59 | AE33: 5.6393486 | AF33: 5.6891328 | AG33: 5.7393565 | AH33: 5.7900235 | AI33: 5.8411379
E34: AGR_RESID_CROP_WHEAT | U34: =AN34*$AU$34 -> 0.76362 | V34: =AO34*$AU$34 -> 0.8208915 | W34: =AP34*$AU$34 -> 0.82813834 | X34: =AQ34*$AU$34 -> 0.83544915 | Y34: =AR34*$AU$34 -> 0.8428245 | Z34: =AS34*$AU$34 -> 0.85026496 | AA34: =AT34*$AU$34 -> 0.8577711 | AN34: =((AF140)/$AF$139)*Y128*0.33 -> 1.52724 | AO34: =((AG140)/AG139)*$Y$128*0.33 -> 1.641783 | AP34: =((AH140)/AH139)*$Y$128*0.33 -> 1.6562767 | AQ34: =((AI140)/AI139)*$Y$128*0.33 -> 1.6708983 | AR34: =((AJ140)/AJ139)*$Y$128*0.33 -> 1.685649 | AS34: =((AK140)/AK139)*$Y$128*0.33 -> 1.7005299 | AT34: =((AL140)/AL139)*$Y$128*0.33 -> 1.7155422 | AU34: 0.5 | AW34: =U34*G28 -> 1821.7629
F35: AGR_N2O | AK35: 0.0014 | AL35: 0.0014
B36: AGR_LAND_CROP_BARLEY | C36: AGR_LAND_CROP_BARLEY | G36: =Y144 -> 695.314 | H36: 620.626 | I36: 671.35791 | J36: 601.65783 | K36: 533.6735 | L36: 467.37186 | M36: 402.72041 | AB36: 1 | AJ36: 1
D37: =AGR_Comm!D63 -> AGR_LAND | N37: 1 | O37: 1 | P37: 1 | Q37: 1 | R37: 1 | S37: 1 | T37: 1
D38: =AGR_Comm!D93 -> AGR_MACH_WORK | N38: =AGR_SVC!N122 -> 0.0030442496 | O38: =AGR_SVC!AP122 -> 0.0030370705 | P38: =AGR_SVC!BD122 -> 0.0027741051 | Q38: =AGR_SVC!BR122 -> 0.0027980839 | R38: =AGR_SVC!CF122 -> 0.0028185575 | S38: =AGR_SVC!CT122 -> 0.0028338342 | T38: =AGR_SVC!AB122 -> 0.0028411038
D39: =AGR_Comm!D94 -> AGR_DRY_SVC | N39: =AGR_SVC!O122 -> 0.00043690604 | O39: =AGR_SVC!AQ122 -> 0.00042784537 | P39: =AGR_SVC!BE122 -> 0.00041914641 | Q39: =AGR_SVC!BS122 -> 0.00049798849 | R39: =AGR_SVC!CG122 -> 0.00061082966 | S39: =AGR_SVC!CU122 -> 0.00078569513 | T39: =AGR_SVC!AC122 -> 0.0010930839
D40: =AGR_Comm!D97 -> AGR_OTH_SVC | N40: =AGR_SVC!R122 -> 0.0013144346 | O40: =AGR_SVC!AT122 -> 0.0013370053 | P40: =AGR_SVC!BH122 -> 0.0013597853 | Q40: =AGR_SVC!BV122 -> 0.0015467707 | R40: =AGR_SVC!CJ122 -> 0.0017819121 | S40: =AGR_SVC!CX122 -> 0.0020862237 | T40: =AGR_SVC!AF122 -> 0.0024950179
E41: AGR_DEM_CROP_BARLEY | AC41: =Z144/10 -> 4.34 | AD41: 4.82 | AE41: 4.8841756 | AF41: 4.9492057 | AG41: 5.0151017 | AH41: 5.081875 | AI41: 5.1495373
E42: AGR_RESID_CROP_BARLEY | U42: =AN42*$AU$42 -> 0.57288 | V42: =AO42*$AU$42 -> 0.63624 | W42: =AP42*$AU$42 -> 0.64471118 | X42: =AQ42*$AU$42 -> 0.65329516 | Y42: =AR42*$AU$42 -> 0.66199342 | Z42: =AS42*$AU$42 -> 0.6708075 | AA42: =AT42*$AU$42 -> 0.67973893 | AN42: =((AF142)/AF141)*$Z$128*0.33 -> 1.14576 | AO42: =((AG142)/AG141)*$Z$128*0.33 -> 1.27248 | AP42: =((AH142)/AH141)*$Z$128*0.33 -> 1.2894224 | AQ42: =((AI142)/AI141)*$Z$128*0.33 -> 1.3065903 | AR42: =((AJ142)/AJ141)*$Z$128*0.33 -> 1.3239868 | AS42: =((AK142)/AK141)*$Z$128*0.33 -> 1.341615 | AT42: =((AL142)/AL141)*$Z$128*0.33 -> 1.3594779 | AU42: 0.5 | AW42: =U42*G36 -> 398.33148
F43: AGR_N2O | AK43: 0.0014 | AL43: 0.0014
B44: AGR_LAND_CROP_MAIZE | C44: AGR_LAND_CROP_MAIZE | G44: =Y152 -> 1276.727 | H44: 1341.812 | I44: 1379.8495 | J44: 1084.356 | K44: 798.94853 | L44: 523.36153 | M44: 257.33578 | AB44: 1 | AJ44: 1
D45: =AGR_Comm!D63 -> AGR_LAND | N45: 1 | O45: 1 | P45: 1 | Q45: 1 | R45: 1 | S45: 1 | T45: 1
D46: =AGR_Comm!D93 -> AGR_MACH_WORK | N46: =AGR_SVC!N123 -> 0.0038053119 | O46: =AGR_SVC!AP123 -> 0.0037963381 | P46: =AGR_SVC!BD123 -> 0.0034676314 | Q46: =AGR_SVC!BR123 -> 0.0034976049 | R46: =AGR_SVC!CF123 -> 0.0035231968 | S46: =AGR_SVC!CT123 -> 0.0035422927 | T46: =AGR_SVC!AB123 -> 0.0035513797
D47: =AGR_Comm!D94 -> AGR_DRY_SVC | N47: =AGR_SVC!O123 -> 0.0025700355 | O47: =AGR_SVC!AQ123 -> 0.0025167374 | P47: =AGR_SVC!BE123 -> 0.0024655671 | Q47: =AGR_SVC!BS123 -> 0.002929344 | R47: =AGR_SVC!CG123 -> 0.0035931156 | S47: =AGR_SVC!CU123 -> 0.004621736 | T47: =AGR_SVC!AC123 -> 0.0064299056
...

Sheet AGR_LIV
E2: ~FI_T:PL
B3: TechName | C3: * TechDesc | D3: Comm-IN | E3: Comm-OUT | F3: Comm-OUT-A | G3: Stock~2024 | H3: Stock~2025 | I3: Stock~2030 | J3: Stock~2035 | K3: Stock~2040 | L3: Stock~2045 | M3: Stock~2050 | N3: Input~2024 | O3: Input~2025 | P3: Input~2030 | Q3: Input~2035 | R3: Input~2040 | S3: Input~2045 | T3: Input~2050 | U3: OUTPUT | V3: Cap2Act | W3: AFA | Y3: Uzysk manure | Z3: Współczynnik zebrania | AB3: Produkcja odpadów max
B4: * Technology name | C4: Technology description | D4: Commodity input | E4: Commodity output | G4: Thousands Animals | H4: Thousands Animals | I4: Thousands Animals | J4: Thousands Animals | K4: Thousands Animals | L4: Thousands Animals | M4: Thousands Animals | N4: Fuel Input per 1000 Animals/Final Energy Demand [PJ/1000 Animals] | U4: kt/1000 animals | V4: Animals per year | AB4: kt | AD4: %
B5: AGR_EX_LIV_CAT_DAIRY | C5: AGR_LIV_CAT_DAIRY | G5: =K75/1000 -> 2101.159 | H5: 2091.035 | I5: 1970.9299 | J5: 1654.0253 | K5: 1426.6884 | L5: 1242.5278 | M5: 1080.1438 | V5: 1 | W5: 1
D6: =$D$70 -> AGR_LIVESTOCK_FOOD | N6: 1 | O6: 1 | P6: 1 | Q6: 1 | R6: 1 | S6: 1 | T6: 1
D7: =AGR_Comm!$D$93 -> AGR_MACH_WORK | N7: =AGR_SVC!N139 -> 0.00024603962 | O7: =AGR_SVC!AP139 -> 0.00024074424 | P7: =AGR_SVC!BD139 -> 0.00023137146 | Q7: =AGR_SVC!BR139 -> 0.00024705137 | R7: =AGR_SVC!CF139 -> 0.00025320281 | S7: =AGR_SVC!CT139 -> 0.00025259298 | T7: =AGR_SVC!AB139 -> 0.000246695
D8: =AGR_Comm!$D$95 -> AGR_LIV_HT | N8: =AGR_SVC!P139 -> 0.00010790472 | O8: =AGR_SVC!AR139 -> 0.00010539017 | P8: =AGR_SVC!BF139 -> 0.00010674852 | Q8: =AGR_SVC!BT139 -> 0.00012116691 | R8: =AGR_SVC!CH139 -> 0.00013347865 | S8: =AGR_SVC!CV139 -> 0.00014522954 | T8: =AGR_SVC!AD139 -> 0.00015782254
D9: =AGR_Comm!$D$96 -> AGR_LIV_ELC_SVC | N9: =AGR_SVC!Q139 -> 0.0003666136 | O9: =AGR_SVC!AS139 -> 0.00040364576 | P9: =AGR_SVC!BG139 -> 0.00064163976 | Q9: =AGR_SVC!BU139 -> 0.0010188578 | R9: =AGR_SVC!CI139 -> 0.0014760099 | S9: =AGR_SVC!CW139 -> 0.002033271 | T9: =AGR_SVC!AE139 -> 0.0027283268
D10: =AGR_Comm!$D$97 -> AGR_OTH_SVC | N10: =AGR_SVC!R139 -> 0.00037755319 | O10: =AGR_SVC!AT139 -> 0.00037446317 | P10: =AGR_SVC!BH139 -> 0.00040066884 | Q10: =AGR_SVC!BV139 -> 0.00048147075 | R10: =AGR_SVC!CJ139 -> 0.00056286953 | S10: =AGR_SVC!CX139 -> 0.00065166672 | T10: =AGR_SVC!AF139 -> 0.00075581473
E11: AGR_DEM_LIV_CAT_DAIRY
E12: AGR_LIV_MANURE_CAT_DAIRY | U12: =Y12*Z12 -> 7.0925 | Y12: 14.185 | Z12: 0.5 | AB12: =U12*M5 -> 7660.9201 | AD12: =AB12/AB64 -> 0.38035369
F13: AGR_CH4_ENT | U13: 0.1056
F14: AGR_CH4_MAN | U14: =0.01438 -> 0.01438
F15: AGR_N2O | U15: =120/1000000 -> 0.00012
B16: AGR_EX_LIV_CAT_NON-DAIRY | C16: AGR_LIV_CAT_NON-DAIRY | G16: =(J75-K75)/1000 -> 4089.768 | H16: 4052.27 | I16: 3819.5153 | J16: 3205.3778 | K16: 2764.8157 | L16: 2407.9263 | M16: 2093.2382 | V16: 1 | W16: 1
D17: =$D$70 -> AGR_LIVESTOCK_FOOD | N17: 1 | O17: 1 | P17: 1 | Q17: 1 | R17: 1 | S17: 1 | T17: 1
D18: =AGR_Comm!$D$93 -> AGR_MACH_WORK | N18: =AGR_SVC!N140 -> 0.00018452971 | O18: =AGR_SVC!AP140 -> 0.00018055818 | P18: =AGR_SVC!BD140 -> 0.00017352859 | Q18: =AGR_SVC!BR140 -> 0.00018528853 | R18: =AGR_SVC!CF140 -> 0.00018990211 | S18: =AGR_SVC!CT140 -> 0.00018944473 | T18: =AGR_SVC!AB140 -> 0.00018502125
D19: =AGR_Comm!$D$95 -> AGR_LIV_HT | N19: =AGR_SVC!P140 -> 5.3952361e-05 | O19: =AGR_SVC!AR140 -> 5.2695086e-05 | P19: =AGR_SVC!BF140 -> 5.3374258e-05 | Q19: =AGR_SVC!BT140 -> 6.0583457e-05 | R19: =AGR_SVC!CH140 -> 6.6739327e-05 | S19: =AGR_SVC!CV140 -> 7.2614772e-05 | T19: =AGR_SVC!AD140 -> 7.8911272e-05
D20: =AGR_Comm!$D$96 -> AGR_LIV_ELC_SVC | N20: =AGR_SVC!Q140 -> 7.3322719e-05 | O20: =AGR_SVC!AS140 -> 8.0729152e-05 | P20: =AGR_SVC!BG140 -> 0.00012832795 | Q20: =AGR_SVC!BU140 -> 0.00020377156 | R20: =AGR_SVC!CI140 -> 0.00029520198 | S20: =AGR_SVC!CW140 -> 0.0004066542 | T20: =AGR_SVC!AE140 -> 0.00054566536
D21: =AGR_Comm!$D$97 -> AGR_OTH_SVC | N21: =AGR_SVC!R140 -> 0.00020765425 | O21: =AGR_SVC!AT140 -> 0.00020595474 | P21: =AGR_SVC!BH140 -> 0.00022036786 | Q21: =AGR_SVC!BV140 -> 0.00026480891 | R21: =AGR_SVC!CJ140 -> 0.00030957824 | S21: =AGR_SVC!CX140 -> 0.00035841669 | T21: =AGR_SVC!AF140 -> 0.0004156981
E22: AGR_DEM_LIV_CAT_NON-DAIRY
E23: AGR_LIV_MANURE_CAT_NON-DAIRY | U23: =Y23*Z23 -> 2.937 | Y23: 5.874 | Z23: 0.5 | AB23: =U23*M16 -> 6147.8407 | AD23: =AB23/AB64 -> 0.30523147
F24: AGR_CH4_ENT | U24: 0.0531
F25: AGR_CH4_MAN | U25: 0.00858
F26: AGR_N2O | U26: 0.000144
B27: AGR_EX_LIV_SHEEP | C27: AGR_LIV_SHEEP | G27: =N75/1000 -> 269.538 | H27: 267.894 | I27: 252.50667 | J27: 211.90628 | K27: 182.7809 | L27: 159.18707 | M27: 138.38317 | V27: 1 | W27: 1
D28: =$D$70 -> AGR_LIVESTOCK_FOOD | N28: 1 | O28: 1 | P28: 1 | Q28: 1 | R28: 1 | S28: 1 | T28: 1
E29: AGR_DEM_LIV_SHEEP
B30: \I: | E30: AGR_LIV_MANURE_SHEEP | U30: =Y30*Z30 -> 0.342 | Y30: 0.684 | Z30: 0.5 | AB30: =U30*M27 -> 47.327044
F31: AGR_CH4_ENT | U31: 0.008
F32: AGR_CH4_MAN | U32: 0.00113
F33: AGR_N2O | U33: 1.8e-05
B34: AGR_EX_LIV_SWINE | C34: AGR_LIV_SWINE | G34: =L75/1000 -> 9078.25 | H34: 9225.221 | I34: 8695.3417 | J34: 7297.2231 | K34: 6294.2588 | L34: 5481.7798 | M34: 4765.3748 | V34: 1 | W34: 1
D35: =$D$70 -> AGR_LIVESTOCK_FOOD | N35: 1 | O35: 1 | P35: 1 | Q35: 1 | R35: 1 | S35: 1 | T35: 1
D36: =AGR_Comm!$D$93 -> AGR_MACH_WORK | N36: =AGR_SVC!N141 -> 4.4287131e-05 | O36: =AGR_SVC!AP141 -> 4.3333964e-05 | P36: =AGR_SVC!BD141 -> 4.1646863e-05 | Q36: =AGR_SVC!BR141 -> 4.4469246e-05 | R36: =AGR_SVC!CF141 -> 4.5576506e-05 | S36: =AGR_SVC!CT141 -> 4.5466736e-05 | T36: =AGR_SVC!AB141 -> 4.44051e-05
D37: =AGR_Comm!$D$95 -> AGR_LIV_HT | N37: =AGR_SVC!P141 -> 0.00033450464 | O37: =AGR_SVC!AR141 -> 0.00032670953 | P37: =AGR_SVC!BF141 -> 0.0003309204 | Q37: =AGR_SVC!BT141 -> 0.00037561743 | R37: =AGR_SVC!CH141 -> 0.00041378383 | S37: =AGR_SVC!CV141 -> 0.00045021158 | T37: =AGR_SVC!AD141 -> 0.00048924988
D38: =AGR_Comm!$D$96 -> AGR_LIV_ELC_SVC | N38: =AGR_SVC!Q141 -> 9.1653399e-05 | O38: =AGR_SVC!AS141 -> 0.00010091144 | P38: =AGR_SVC!BG141 -> 0.00016040994 | Q38: =AGR_SVC!BU141 -> 0.00025471445 | R38: =AGR_SVC!CI141 -> 0.00036900248 | S38: =AGR_SVC!CW141 -> 0.00050831775 | T38: =AGR_SVC!AE141 -> 0.00068208169
D39: =AGR_Comm!$D$97 -> AGR_OTH_SVC | N39: =AGR_SVC!R141 -> 0.00030204255 | O39: =AGR_SVC!AT141 -> 0.00029957054 | P39: =AGR_SVC!BH141 -> 0.00032053507 | Q39: =AGR_SVC!BV141 -> 0.0003851766 | R39: =AGR_SVC!CJ141 -> 0.00045029562 | S39: =AGR_SVC!CX141 -> 0.00052133337 | T39: =AGR_SVC!AF141 -> 0.00060465178
E40: AGR_DEM_LIV_SWINE
E41: AGR_LIV_MANURE_SWINE | U41: =Y41*Z41 -> 1.033 | Y41: 2.066 | Z41: 0.5 | AB41: =U41*M34 -> 4922.6322 | AD41: =AB41/AB64 -> 0.24440162
...

Sheet AGR_SVC
B2: Usługi rolnicze | Agricultural services | AG2: Zmienić wartości dla roku bazowego i 2050 w dużych tabelach niżej - interpolacja i obliczenie nowych wartości formułami
E4: ~FI_T:PL | AO4: Interpolacja
B5: TechName | C5: *TechDesc | D5: Comm-IN | E5: Comm-OUT | F5: Share-I~2024 | G5: Share-I~2025 | H5: Share-I~2030 | I5: Share-I~2035 | J5: Share-I~2040 | K5: Share-I~2045 | L5: Share-I~2050 | M5: Stock~2024 | N5: Stock~2025 | O5: Stock~2030 | P5: Stock~2035 | Q5: Stock~2040 | R5: Stock~2045 | S5: Stock~2050 | T5: ACTFLO | U5: CEFF | V5: VAROM | W5: FIXOM | X5: Cap2Act | Y5: Share-I~0 | AA5: Check | AC5: Check | AF5: Paliwo/nośnik | AG5: 2024 | AH5: 2025 | AI5: 2030 | AJ5: 2035 | AK5: 2040 | AL5: 2045 | AM5: 2050
B6: * Technology name | C6: Technology description | D6: Commodity input | E6: Commodity output | F6: Fuel share | U6: % | X6: PJ/PJ | AA6: 2024 | AC6: 2050
B7: =AGR_Proc!D72 -> AGR_PRC_MECH_WORK | C7: Mechanical Work for Agriculture | D7: =SECTF!E12 -> AGR_OIL_GSL | F7: =N65/N70 -> 0.0012003485 | G7: =AP65/AP70 -> 0.0012226855 | H7: =BD65/BD70 -> 0.0013490979 | I7: =BR65/BR70 -> 0.0015067234 | J7: =CF65/CF70 -> 0.0017087503 | K7: =CT65/CT70 -> 0.0019770157 | L7: =AB65/AB70 -> 0.0023504832 | M7: =N104 -> 23.352102 | N7: =AP104 -> 22.920578 | O7: =BD104 -> 20.762963 | P7: =BR104 -> 18.605347 | Q7: =CF104 -> 16.447731 | R7: =CT104 -> 14.290116 | S7: =AB104 -> 12.1325 | U7: =N84 -> 0.25 | X7: 1 | Y7: 1 | AA7: =M7*X7/(F7*U7+F8*U8+F9*U9) -> 77.330809 | AB7: =AA7=N72 -> TRUE | AC7: =S7*X7/(L7*U7+L8*U8+L9*U9) -> 38.29 | AD7: =AC7=AB72 -> TRUE | AF7: Węgiel kamienny en. | AG7: =G57 -> 13000 | AH7: =ROUND(AG7+AO7, 6) -> 12500 | AI7: =ROUND(AH7+(5*AO7),6) -> 10000 | AJ7: =ROUND(AI7+(5*AO7),6) -> 7500 | AK7: =ROUND(AJ7+(5*AO7),6) -> 5000 | AL7: =ROUND(AK7+(5*AO7),6) -> 2500 | AM7: =U57 -> 0 | AO7: =(AM7-AG7)/26 -> -500
D8: =SECTF!E14 -> AGR_OIL_DSL | F8: =N66/N70 -> 0.99472624 | G8: =AP66/AP70 -> 0.99412364 | H8: =BD66/BD70 -> 0.9907133 | I8: =BR66/BR70 -> 0.98646091 | J8: =CF66/CF70 -> 0.98101066 | K8: =CT66/CT70 -> 0.97377344 | L8: =AB66/AB70 -> 0.96369809 | U8: =N85 -> 0.3 | Y8: 1 | AF8: Węgiel brunatny | AG8: =G58 -> 160 | AH8: =ROUND(AG8+AO8, 6) -> 153.84615 | AI8: =ROUND(AH8+(5*AO8),6) -> 123.07692 | AJ8: =ROUND(AI8+(5*AO8),6) -> 92.307692 | AK8: =ROUND(AJ8+(5*AO8),6) -> 61.538461 | AL8: =ROUND(AK8+(5*AO8),6) -> 30.76923 | AM8: =U58 -> 0 | AO8: =(AM8-AG8)/26 -> -6.1538462
D9: =SECTF!E30 -> AGR_ELC | F9: =N68/N70 -> 0.0040734088 | G9: =AP68/AP70 -> 0.0046536747 | H9: =BD68/BD70 -> 0.0079375973 | I9: =BR68/BR70 -> 0.012032365 | J9: =CF68/CF70 -> 0.017280589 | K9: =CT68/CT70 -> 0.024249544 | L9: =AB68/AB70 -> 0.033951423 | U9: =N87 -> 0.8 | Y9: 1 | AF9: Gaz ziemny razem | AG9: =G59 -> 1847.8184 | AH9: =ROUND(AG9+AO9, 6) -> 1815.21 | AI9: =ROUND(AH9+(5*AO9),6) -> 1652.168 | AJ9: =ROUND(AI9+(5*AO9),6) -> 1489.126 | AK9: =ROUND(AJ9+(5*AO9),6) -> 1326.084 | AL9: =ROUND(AK9+(5*AO9),6) -> 1163.042 | AM9: =U59 -> 1000 | AO9: =(AM9-AG9)/26 -> -32.6084
E10: =AGR_Comm!D93 -> AGR_MACH_WORK | AF10: Torf i drewno | AG10: =G60 -> 16349.378 | AH10: =ROUND(AG10+AO10, 6) -> 16105.171 | AI10: =ROUND(AH10+(5*AO10),6) -> 14884.137 | AJ10: =ROUND(AI10+(5*AO10),6) -> 13663.103 | AK10: =ROUND(AJ10+(5*AO10),6) -> 12442.069 | AL10: =ROUND(AK10+(5*AO10),6) -> 11221.034 | AM10: =U60 -> 10000 | AO10: =(AM10-AG10)/26 -> -244.20685
B11: =AGR_Proc!D73 -> AGR_PRC_DRY_SVC | C11: Crop Drying | D11: =SECTF!E8 -> AGR_HC | F11: =O57/O70 -> 0.17413256 | G11: =AQ57/AQ70 -> 0.16811989 | H11: =BE57/BE70 -> 0.13730349 | I11: =BS57/BS70 -> 0.10517308 | J11: =CG57/CG70 -> 0.071642804 | K11: =CU57/CU70 -> 0.036619123 | L11: =AC57/AC70 -> 0 | M11: =O104 -> 5.5134243 | N11: =AQ104 -> 5.5054657 | O11: =BE104 -> 5.4656725 | P11: =BS104 -> 5.4258794 | Q11: =CG104 -> 5.3860863 | R11: =CU104 -> 5.3462931 | S11: =AC104 -> 5.3065 | U11: =O76 -> 0.65 | X11: 1 | Y11: 1 | AF11: Biogaz | AG11: =G61 -> 556.87786 | AH11: =ROUND(AG11+AO11, 6) -> 823.92102 | AI11: =ROUND(AH11+(5*AO11),6) -> 2159.1368 | AJ11: =ROUND(AI11+(5*AO11),6) -> 3494.3526 | AK11: =ROUND(AJ11+(5*AO11),6) -> 4829.5684 | AL11: =ROUND(AK11+(5*AO11),6) -> 6164.7842 | AM11: =U61 -> 7500 | AO11: =(AM11-AG11)/26 -> 267.04316
D12: =SECTF!E10 -> AGR_BC | F12: =O58/O70 -> 0.00214317 | G12: =AQ58/AQ70 -> 0.0020691679 | H12: =BE58/BE70 -> 0.0016898891 | I12: =BS58/BS70 -> 0.001294438 | J12: =CG58/CG70 -> 0.00088175758 | K12: =CU58/CU70 -> 0.00045069689 | L12: =AC58/AC70 -> 0 | U12: =O77 -> 0.6 | Y12: 1 | AF12: Paliwa odpadowe i ciekłe bio. | AG12: =G62 -> 41.77884 | AH12: =ROUND(AG12+AO12, 6) -> 136.32581 | AI12: =ROUND(AH12+(5*AO12),6) -> 609.06065 | AJ12: =ROUND(AI12+(5*AO12),6) -> 1081.7955 | AK12: =ROUND(AJ12+(5*AO12),6) -> 1554.5303 | AL12: =ROUND(AK12+(5*AO12),6) -> 2027.2652 | AM12: =U62 -> 2500 | AO12: =(AM12-AG12)/26 -> 94.546968
D13: =SECTF!E20 -> AGR_NAT_GAS | F13: =O59/O70 -> 0.11138031 | G13: =AQ59/AQ70 -> 0.10986225 | H13: =BE59/BE70 -> 0.10208179 | I13: =BS59/BS70 -> 0.093969585 | J13: =CG59/CG70 -> 0.085503938 | K13: =CU59/CU70 -> 0.076661241 | L13: =AC59/AC70 -> 0.06741573 | U13: =O78 -> 0.8 | Y13: 1 | AF13: Brykiety, koks i półkoks | AG13: =G63 -> 47.0832 | AH13: =ROUND(AG13+AO13, 6) -> 45.272308 | AI13: =ROUND(AH13+(5*AO13),6) -> 36.217846 | AJ13: =ROUND(AI13+(5*AO13),6) -> 27.163384 | AK13: =ROUND(AJ13+(5*AO13),6) -> 18.108922 | AL13: =ROUND(AK13+(5*AO13),6) -> 9.05446 | AM13: =U63 -> 0 | AO13: =(AM13-AG13)/26 -> -1.8108923
D14: =SECTF!E24 -> AGR_BIOM | F14: =O60/O70 -> 0.21899685 | G14: =AQ60/AQ70 -> 0.21660797 | H14: =BE60/BE70 -> 0.2043644 | I14: =BS60/BS70 -> 0.19159876 | J14: =CG60/CG70 -> 0.17827693 | K14: =CU60/CU70 -> 0.16436177 | L14: =AC60/AC70 -> 0.14981273 | U14: =O79 -> 0.68 | Y14: 1 | AF14: Gaz ciekły | AG14: =G64 -> 1840 | AH14: =ROUND(AG14+AO14, 6) -> 1788.4615 | AI14: =ROUND(AH14+(5*AO14),6) -> 1530.7692 | AJ14: =ROUND(AI14+(5*AO14),6) -> 1273.0769 | AK14: =ROUND(AJ14+(5*AO14),6) -> 1015.3846 | AL14: =ROUND(AK14+(5*AO14),6) -> 757.69231 | AM14: =U64 -> 500 | AO14: =(AM14-AG14)/26 -> -51.538462
D15: =SECTF!E22 -> AGR_BIOG | F15: =O61/O70 -> 0.0074592743 | G15: =AQ61/AQ70 -> 0.011081401 | H15: =BE61/BE70 -> 0.029645702 | I15: =BS61/BS70 -> 0.049001579 | J15: =CG61/CG70 -> 0.069200764 | K15: =CU61/CU70 -> 0.090299597 | L15: =AC61/AC70 -> 0.11235955 | U15: =O80 -> 0.75 | Y15: 1 | AF15: Benzyny silnikowe i lotnicze | AG15: =G65 -> 103.13769 | AH15: =ROUND(AG15+AO15, 6) -> 103.01701 | AI15: =ROUND(AH15+(5*AO15),6) -> 102.41361 | AJ15: =ROUND(AI15+(5*AO15),6) -> 101.81021 | AK15: =ROUND(AJ15+(5*AO15),6) -> 101.20681 | AL15: =ROUND(AK15+(5*AO15),6) -> 100.6034 | AM15: =U65 -> 100 | AO15: =(AM15-AG15)/26 -> -0.12068046
D16: =SECTF!E33 -> AGR_OTH_FUE | F16: =(O62+O63)/O70 -> 0.0011902903 | G16: =(AQ62+AQ63)/AQ70 -> 0.0024424205 | H16: =(BE62+BE63)/BE70 -> 0.0088598989 | I16: =(BS62+BS63)/BS70 -> 0.015551017 | J16: =(CG62+CG63)/CG70 -> 0.022533657 | K16: =(CU62+CU63)/CU70 -> 0.029827296 | L16: =(AC62+AC63)/AC70 -> 0.037453184 | U16: =(O81+O82)/2 -> 0.65 | Y16: 1 | AF16: Oleje napędowe | AG16: =G66 -> 85469.984 | AH16: =ROUND(AG16+AO16, 6) -> 83759.6 | AI16: =ROUND(AH16+(5*AO16),6) -> 75207.68 | AJ16: =ROUND(AI16+(5*AO16),6) -> 66655.76 | AK16: =ROUND(AJ16+(5*AO16),6) -> 58103.84 | AL16: =ROUND(AK16+(5*AO16),6) -> 49551.92 | AM16: =U66 -> 41000 | AO16: =(AM16-AG16)/26 -> -1710.384
D17: =SECTF!E16 -> AGR_OIL_LPG | F17: =O64/O70 -> 0.086262591 | G17: =AQ64/AQ70 -> 0.08418927 | H17: =BE64/BE70 -> 0.073562985 | I17: =BS64/BS70 -> 0.062483599 | J17: =CG64/CG70 -> 0.0509215 | K17: =CU64/CU70 -> 0.038844439 | L17: =AC64/AC70 -> 0.026217228 | U17: =O83 -> 0.8 | Y17: 1 | AF17: Oleje opałowe | AG17: =G67 -> 3094.6173 | AH17: =ROUND(AG17+AO17, 6) -> 2975.5936 | AI17: =ROUND(AH17+(5*AO17),6) -> 2380.4749 | AJ17: =ROUND(AI17+(5*AO17),6) -> 1785.3562 | AK17: =ROUND(AJ17+(5*AO17),6) -> 1190.2374 | AL17: =ROUND(AK17+(5*AO17),6) -> 595.11872 | AM17: =U67 -> 0 | AO17: =(AM17-AG17)/26 -> -119.02374
D18: =SECTF!E14 -> AGR_OIL_DSL | F18: =O66/O70 -> 0.11448544 | G18: =AQ66/AQ70 -> 0.11265324 | H18: =BE66/BE70 -> 0.10326277 | I18: =BS66/BS70 -> 0.093471892 | J18: =CG66/CG70 -> 0.08325444 | K18: =CU66/CU70 -> 0.072581915 | L18: =AC66/AC70 -> 0.061423221 | U18: =O85 -> 0.75 | Y18: 1 | AA18: =M11*X11/(F11*U11+F12*U12+F13*U13+F14*U14+F15*U15+F16*U16+F17*U17+F18*U18+F19*U19+F20*U20) -> 7.4655769 | AB18: =AA18=O72 -> TRUE | AC18: =S11*X11/(L11*U11+L12*U12+L13*U13+L14*U14+L15*U15+L16*U16+L17*U17+L18*U18+L19*U19+L20*U20) -> 6.675 | AD18: =AC18=AC72 -> TRUE | AF18: Energia elektryczna | AG18: =G68 -> 6300 | AH18: =ROUND(AG18+AO18, 6) -> 7057.6923 | AI18: =ROUND(AH18+(5*AO18),6) -> 10846.154 | AJ18: =ROUND(AI18+(5*AO18),6) -> 14634.615 | AK18: =ROUND(AJ18+(5*AO18),6) -> 18423.077 | AL18: =ROUND(AK18+(5*AO18),6) -> 22211.538 | AM18: =U68 -> 26000 | AO18: =(AM18-AG18)/26 -> 757.69231
D19: =SECTF!E18 -> AGR_OIL_FUE | F19: =O67/O70 -> 0.16580727 | G19: =AQ67/AQ70 -> 0.16008207 | H19: =BE67/BE70 -> 0.130739 | I19: =BS67/BS70 -> 0.10014475 | J19: =CG67/CG70 -> 0.068217558 | K19: =CU67/CU70 -> 0.034868361 | L19: =AC67/AC70 -> 0 | U19: =O86 -> 0.75 | Y19: 1 | AF19: Ciepło | AG19: =G69 -> 620 | AH19: =ROUND(AG19+AO19, 6) -> 711.53846 | AI19: =ROUND(AH19+(5*AO19),6) -> 1169.2308 | AJ19: =ROUND(AI19+(5*AO19),6) -> 1626.9231 | AK19: =ROUND(AJ19+(5*AO19),6) -> 2084.6154 | AL19: =ROUND(AK19+(5*AO19),6) -> 2542.3077 | AM19: =U69 -> 3000 | AO19: =(AM19-AG19)/26 -> 91.538462
D20: =SECTF!E30 -> AGR_ELC | F20: =O68/O70 -> 0.11814224 | G20: =AQ68/AQ70 -> 0.13289231 | H20: =BE68/BE70 -> 0.20849007 | I20: =BS68/BS70 -> 0.28731129 | J20: =CG68/CG70 -> 0.36956665 | K20: =CU68/CU70 -> 0.45548556 | L20: =AC68/AC70 -> 0.54531835 | U20: =O87 -> 0.85 | Y20: 1 | AF20: Suma | AG20: =SUM(AG7:AG19) -> 129430.68 | AH20: =SUM(AH7:AH19) -> 127975.65 | AI20: =SUM(AI7:AI19) -> 120700.52 | AJ20: =SUM(AJ7:AJ19) -> 113425.39 | AK20: =SUM(AK7:AK19) -> 106150.26 | AL20: =SUM(AL7:AL19) -> 98875.13 | AM20: =SUM(AM7:AM19) -> 91600
E21: =AGR_Comm!D94 -> AGR_DRY_SVC
B22: =AGR_Proc!D74 -> AGR_PRC_LIV_HT | C22: Livestock Space Heating | D22: =SECTF!E8 -> AGR_HC | F22: =P57/P70 -> 0.39642403 | G22: =AR57/AR70 -> 0.38534184 | H22: =BF57/BF70 -> 0.32608831 | I22: =BT57/BT70 -> 0.25956632 | J22: =CH57/CH70 -> 0.18435111 | K22: =CV57/CV70 -> 0.098619453 | L22: =AD57/AD70 -> 0 | M22: =P104 -> 10.73698 | N22: =AR104 -> 10.640598 | O22: =BF104 -> 10.158688 | P22: =BT104 -> 9.6767787 | Q22: =CH104 -> 9.1948691 | R22: =CV104 -> 8.7129596 | S22: =AD104 -> 8.23105 | U22: =P76 -> 0.7 | X22: 1 | Y22: 1
D23: =SECTF!E10 -> AGR_BC | F23: =P58/P70 -> 0.0043369467 | G23: =AR58/AR70 -> 0.0042157056 | H23: =BF58/BF70 -> 0.0035674618 | I23: =BT58/BT70 -> 0.0028396999 | J23: =CH58/CH70 -> 0.0020168326 | K23: =CV58/CV70 -> 0.0010789136 | L23: =AD58/AD70 -> 0 | U23: =P77 -> 0.6 | Y23: 1
D24: =SECTF!E20 -> AGR_NAT_GAS | F24: =P59/P70 -> 0.037565109 | G24: =AR59/AR70 -> 0.037305406 | H24: =BF59/BF70 -> 0.035916844 | I24: =BT59/BT70 -> 0.034357952 | J24: =CH59/CH70 -> 0.032595341 | K24: =CV59/CV70 -> 0.030586284 | L24: =AD59/AD70 -> 0.028275212 | U24: =P78 -> 0.85 | Y24: 1
D25: =SECTF!E24 -> AGR_BIOM | F25: =P60/P70 -> 0.38776927 | G25: =AR60/AR70 -> 0.38615088 | H25: =BF60/BF70 -> 0.37749779 | I25: =BT60/BT70 -> 0.36778325 | J25: =CH60/CH70 -> 0.35679919 | K25: =CV60/CV70 -> 0.34427937 | L25: =AD60/AD70 -> 0.32987747 | U25: =P79 -> 0.7 | Y25: 1
D26: =SECTF!E22 -> AGR_BIOG | F26: =P61/P70 -> 0.020755192 | G26: =AR61/AR70 -> 0.031043588 | H26: =BF61/BF70 -> 0.08605291 | I26: =BT61/BT70 -> 0.14781006 | J26: =CH61/CH70 -> 0.21763776 | K26: =CV61/CV70 -> 0.29722863 | L26: =AD61/AD70 -> 0.38878417 | U26: =P80 -> 0.8 | Y26: 1
D27: =SECTF!E33 -> AGR_OTH_FUE | F27: =(P62+P63)/P70 -> 0.0025682162 | G27: =(AR62+AR63)/Q70 -> 0.018703739 | H27: =(BF62+BF63)/BF70 -> 0.018835026 | I27: =(BT62+BT63)/BT70 -> 0.034219818 | J27: =(CH62+CH63)/CH70 -> 0.051615126 | K27: =(CV62+CV63)/CV70 -> 0.071442612 | L27: =(AD62+AD63)/AD70 -> 0.094250707 | U27: =(P81+P82)/2 -> 0.7 | Y27: 1
D28: =SECTF!E16 -> AGR_OIL_LPG | F28: =P64/P70 -> 0.056109248 | G28: =AR64/AR70 -> 0.055133525 | H28: =BF64/BF70 -> 0.049916595 | I28: =BT64/BT70 -> 0.044059719 | J28: =CH64/CH70 -> 0.037437456 | K28: =CV64/CV70 -> 0.02988928 | L28: =AD64/AD70 -> 0.021206409 | U28: =P83 -> 0.85 | Y28: 1
D29: =SECTF!E18 -> AGR_OIL_FUE | F29: =P67/P70 -> 0.073397135 | G29: =AR67/AR70 -> 0.071345289 | H29: =BF67/BF70 -> 0.060374613 | I29: =BT67/BT70 -> 0.048058198 | J29: =CH67/CH70 -> 0.034132247 | K29: =CV67/CV70 -> 0.018259199 | L29: =AD67/AD70 -> 0 | U29: =P86 -> 0.8 | Y29: 1 | AA29: =M22*X22/(F22*U22+F23*U23+F24*U24+F25*U25+F26*U26+F27*U27+F28*U28+F29*U29+F30*U30+F31*U31) -> 14.756926 | AB29: =AA29=P72 -> TRUE | AC29: =S22*X22/(L22*U22+L23*U23+L24*U24+L25*U25+L26*U26+L27*U27+L28*U28+L29*U29+L30*U30+L31*U31) -> 10.61 | AD29: =AC29=AD72 -> TRUE
D30: =SECTF!E30 -> AGR_ELC | F30: =P68/P70 -> 0.0042691819 | G30: =AR68/AR70 -> 0.0048348874 | H30: =BF68/BF70 -> 0.0078595643 | I30: =BT68/BT70 -> 0.011255269 | J30: =CH68/CH70 -> 0.015094732 | K30: =CV68/CV70 -> 0.01947102 | L30: =AD68/AD70 -> 0.024505184 | U30: =P87 -> 0.98 | Y30: 1
D31: =SECTF!E32 -> AGR_DH | F31: =P69/P70 -> 0.016805668 | G31: =AR69/AR70 -> 0.019497638 | H31: =BF69/BF70 -> 0.033890887 | I31: =BT69/BT70 -> 0.050049712 | J31: =CH69/CH70 -> 0.068320205 | K31: =CV69/CV70 -> 0.089145242 | L31: =AD69/AD70 -> 0.11310085 | U31: =P88 -> 0.9 | Y31: 1 | AA31: =M33*X33/(F33*U33+F34*U34) -> 4.0046998 | AB31: =AA31=Q72 -> TRUE | AC31: =S33*X33/(L33*U33+L34*U34) -> 13.41 | AD31: =AC31=AE72 -> TRUE
E32: =AGR_Comm!D95 -> AGR_LIV_HT
B33: =AGR_Proc!D75 -> AGR_PRC_LIV_ELC_SVC | C33: Livestock Electricity Services | D33: =SECTF!E14 -> AGR_OIL_DSL | F33: =Q66/Q70 -> 0.21342419 | G33: =AS66/AS70 -> 0.19182574 | H33: =BG66/BG70 -> 0.12179078 | I33: =BU66/BU70 -> 0.083488082 | J33: =CI66/CI70 -> 0.059334576 | K33: =CW66/CW70 -> 0.042712428 | L33: =AE66/AE70 -> 0.030574198 | M33: =Q104 -> 3.380769 | N33: =AS104 -> 3.7549971 | O33: =BG104 -> 5.6261377 | P33: =BU104 -> 7.4972782 | Q33: =CI104 -> 9.3684188 | R33: =CW104 -> 11.239559 | S33: =AE104 -> 13.1107 | U33: =Q85 -> 0.27 | X33: 1 | Y33: 1
D34: =SECTF!E30 -> AGR_ELC | F34: =Q68/Q70 -> 0.78657581 | G34: =AS68/AS70 -> 0.80817426 | H34: =BG68/BG70 -> 0.87820922 | I34: =BU68/BU70 -> 0.91651192 | J34: =CI68/CI70 -> 0.94066542 | K34: =CW68/CW70 -> 0.95728757 | L34: =AE68/AE70 -> 0.9694258 | U34: =Q87 -> 1 | Y34: 1
E35: =AGR_Comm!D96 -> AGR_LIV_ELC_SVC
B36: =AGR_Proc!D76 -> AGR_PRC_OTH_SVC | C36: Other Services for Agriculture | D36: =SECTF!E8 -> AGR_HC | F36: =R57/R70 -> 0.22610737 | G36: =AT57/AT70 -> 0.21846893 | H36: =BH57/BH70 -> 0.17913374 | I36: =BV57/BV70 -> 0.13778648 | J36: =CJ57/CJ70 -> 0.094268684 | K36: =CX57/CX70 -> 0.048404848 | L36: =AF57/AF70 -> 0 | M36: =R104 -> 16.036933 | N36: =AT104 -> 16.06432 | O36: =BH104 -> 16.201256 | P36: =BV104 -> 16.338192 | Q36: =CJ104 -> 16.475128 | R36: =CX104 -> 16.612064 | S36: =AF104 -> 16.749 | U36: =R76 -> 0.7 | X36: 1 | Y36: 1
D37: =SECTF!E10 -> AGR_BC | F37: =R58/R70 -> 0.0030920667 | G37: =AT58/AT70 -> 0.0029876092 | H37: =BH58/BH70 -> 0.0024496922 | I37: =BV58/BV70 -> 0.0018842595 | J37: =CJ58/CJ70 -> 0.0012891444 | K37: =CX58/CX70 -> 0.00066194662 | L37: =AF58/AF70 -> 0 | U37: =R77 -> 0.6 | Y37: 1
D38: =SECTF!E20 -> AGR_NAT_GAS | F38: =R59/R70 -> 0.01785493 | G38: =AT59/AT70 -> 0.017625199 | H38: =BH59/BH70 -> 0.016442169 | I38: =BV59/BV70 -> 0.015198624 | J38: =CJ59/CJ70 -> 0.013889799 | K38: =CX59/CX70 -> 0.012510416 | L38: =AF59/AF70 -> 0.01105461 | U38: =R78 -> 0.85 | Y38: 1
D39: =SECTF!E24 -> AGR_BIOM | F39: =R60/R70 -> 0.3475544 | G39: =AT60/AT70 -> 0.3440291 | H39: =BH60/BH70 -> 0.32587515 | I39: =BV60/BV70 -> 0.30679257 | J39: =CJ60/CJ70 -> 0.28670826 | K39: =CX60/CX70 -> 0.2655412 | L39: =AF60/AF70 -> 0.24320141 | U39: =R79 -> 0.7 | Y39: 1
D40: =SECTF!E22 -> AGR_BIOG | F40: =R61/R70 -> 0.0075333276 | G40: =AT61/AT70 -> 0.011200071 | H40: =BH61/BH70 -> 0.030082443 | I40: =BV61/BV70 -> 0.049930692 | J40: =CJ61/CJ70 -> 0.070820876 | K40: =CX61/CX70 -> 0.092837248 | L40: =AF61/AF70 -> 0.1160734 | U40: =R80 -> 0.8 | Y40: 1
D41: =SECTF!E33 -> AGR_OTH_FUE | F41: =(R62+R63)/R70 -> 0.0016263057 | G41: =(AT62+AT63)/AT70 -> 0.003438621 | H41: =(BH62+BH63)/BH70 -> 0.012771374 | I41: =(BV62+BV63)/BV70 -> 0.02258152 | J41: =(CJ62+CJ63)/CJ70 -> 0.032906649 | K41: =(CX62+CX63)/CX70 -> 0.043788406 | L41: =(AF62+AF63)/AF70 -> 0.055273049 | U41: =(R81+R82)/2 -> 0.7 | Y41: 1
D42: =SECTF!E16 -> AGR_OIL_LPG | F42: =R64/R70 -> 0.014223507 | G42: =AT64/AT70 -> 0.013892383 | H42: =BH64/BH70 -> 0.012187219 | I42: =BV64/BV70 -> 0.010394832 | J42: =CJ64/CJ70 -> 0.008508353 | K42: =CX64/CX70 -> 0.0065201744 | L42: =AF64/AF70 -> 0.0044218439 | U42: =R83 -> 0.85 | Y42: 1
...

Sheet AGR_BIOG
F2: ~FI_T:PL
B3: TechName | C3: *TechDesc | D3: Comm-IN | E3: Comm-OUT | F3: Stock~2024 | G3: Stock~2025 | H3: Stock~2030 | I3: Stock~2035 | J3: Stock~2040 | K3: Stock~2045 | L3: Stock~2050 | M3: * Gross Calorific Value | N3: ACTFLO | O3: CEFF | P3: Share-I | Q3: VAROM | R3: FIXOM | S3: Cap2Act | T3: FLO_COST | U3: AFA~FX | V3: Share-I~0
B4: * Technology name | C4: Technology description | D4: Commodity input | E4: Commodity output | F4: mln m3 biogazu na rok | G4: mln m3 biogazu na rok | H4: mln m3 biogazu na rok | I4: mln m3 biogazu na rok | J4: mln m3 biogazu na rok | K4: mln m3 biogazu na rok | L4: mln m3 biogazu na rok | M4: MJ / m3 | N4: PJ/mln m3 - | O4: mln m3 / kt | P4: kt animal manure / kt all manure | S4: kt/kt | T4: PLN /m3 | AA4: Produkcja biogazu | AF4: Wartości oryginalne ,,Biometan w miksie energetycznym Polski'' NCBR | AG4: Wartości użyte: obniżone do poziomu 95% jako osiągalne w skali przemysłowej na rzeczywistych instalacjach biometanowych. Źródło NCBR.
B5: =AGR_Proc!D26 -> AGR_EX_BIOG | C5: =AGR_Proc!E26 -> Agriculture Existing Biogass | F5: 374 | G5: 374 | H5: 374 | I5: 374 | J5: 374 | K5: 374 | L5: 374 | Q5: =E36*F42/1000*F48 -> 0.575 | S5: 1 | U5: 1 | AA5: mln m3 | AF5: 0.322 | AG5: =AF5*0.95 -> 0.3059
D6: AGR_RESID_CROP_WHEAT | O6: 0.3059 | P6: 0.0395034 | T6: =E36*$F$46/(O6*1000) -> 0.1471069 | V6: 3 | AA6: =O6*AGR_LAND!$U$34*AGR_LAND!$G$28 -> 557.27727 | AF6: 0.322 | AG6: =AF6*0.95 -> 0.3059
D7: AGR_RESID_CROP_BARLEY | O7: 0.3059 | P7: 0.0084102 | T7: =E36*$F$46/(O7*1000) -> 0.1471069 | V7: 3 | AA7: =O7*AGR_LAND!$U$42*AGR_LAND!$G$36 -> 121.8496 | AF7: 0.409 | AG7: =AF7*0.95 -> 0.38855
D8: AGR_RESID_CROP_MAIZE | O8: 0.38855 | P8: 0.0212706 | T8: =E36*$F$46/(O8*1000) -> 0.11581521 | V8: 3 | AA8: =O8*AGR_LAND!$U$50*AGR_LAND!$G$44 -> 783.15922 | AF8: 0.322 | AG8: =AF8*0.95 -> 0.3059
D9: AGR_RESID_CROP_CER-MIX | O9: 0.3059 | P9: 0.0065585 | T9: =E36*$F$46/(O9*1000) -> 0.1471069 | V9: 3 | AA9: =O9*AGR_LAND!$U$58*AGR_LAND!$G$52 -> 37.836349 | AF9: 0.322 | AG9: =AF9*0.95 -> 0.3059
D10: AGR_RESID_CROP_TRITICALE | O10: 0.3059 | P10: 0.0238757 | T10: =E36*$F$46/(O10*1000) -> 0.1471069 | V10: 3 | AA10: =O10*AGR_LAND!$U$66*AGR_LAND!$G$60 -> 280.21093 | AF10: 0.322 | AG10: =AF10*0.95 -> 0.3059
D11: AGR_RESID_CROP_OATS | O11: 0.3059 | P11: 0.0063897 | T11: =E36*$F$46/(O11*1000) -> 0.1471069 | V11: 3 | AA11: =O11*AGR_LAND!$U$74*AGR_LAND!$G$68 -> 91.345096 | AF11: 0.322 | AG11: =AF11*0.95 -> 0.3059
D12: AGR_RESID_CROP_RYE | O12: 0.3059 | P12: 0.0580063 | T12: =E36*$F$46/(O12*1000) -> 0.1471069 | V12: 3 | AA12: =AGR_LAND!$U$82*AGR_LAND!$G$76 -> 562.57421 | AF12: 0.322 | AG12: =AF12*0.95 -> 0.3059
D13: AGR_RESID_CROP_MILL-BUCK | O13: 0.3059 | P13: 0.0008202 | T13: =E36*$F$46/(O13*1000) -> 0.1471069 | V13: 3 | Y13: AGR_LIV_MANURE_RABBIT | AA13: =O13*AGR_LAND!$U$90*AGR_LAND!$G$84 -> 15.901874 | AF13: 0 | AG13: =AF13*0.95 -> 0
D14: AGR_LIV_MANURE_CAT_DAIRY | O14: 0.09785 | P14: 0.3757413 | T14: =E36*$F$45/(O14*1000) -> 0.59785386 | V14: 3 | Y14: AGR_LIV_MANURE_FUR | AA14: =#REF!*AGR_LAND!$U$95*AGR_LAND!$G$92 -> #REF! | AF14: 0 | AG14: =AF14*0.95 -> 0
D15: AGR_LIV_MANURE_CAT_NON-DAIRY | O15: 0.09785 | P15: 0.241698 | T15: =E36*$F$45/(O15*1000) -> 0.59785386 | V15: 3 | AA15: =#REF!*AGR_LAND!$U$100*AGR_LAND!$G$97 -> #REF! | AF15: 0 | AG15: =AF15*0.95 -> 0
D16: AGR_LIV_MANURE_SWINE | O16: 0.011875 | P16: 0.1680845 | T16: =E36*$F$45/(O16*1000) -> 4.9263158 | V16: 3 | X16: 0.071862 | Y16: AGR_RESID_CROP_PULS-FEED | AA16: =#REF!*AGR_LAND!$U$105*AGR_LAND!$G$102 -> #REF! | AF16: 0 | AG16: =AF16*0.95 -> 0
B17: =IF(O17>0,"","\I:") | D17: AGR_LIV_MANURE_POULTRY | O17: 0.08835 | P17: 0.0491548 | T17: =E36*$F$45/(O17*1000) -> 0.66213922 | V17: 3 | X17: 0.039538 | Y17: AGR_RESID_CROP_PULS-EDIB | AA17: =#REF!*AGR_LAND!$U$110*AGR_LAND!$G$107 -> #REF! | AF17: 0 | AG17: =AF17*0.95 -> 0
E18: =AGR_Comm!D14 -> PRI_BIOG_AGR | M18: 23 | N18: =M18/1000 -> 0.023 | AA18: =#REF!*AGR_LAND!$U$115*AGR_LAND!$G$112 -> #REF! | AC18: suma_land | AF18: 0 | AG18: =AF18*0.95 -> 0
AA19: =#REF!*AGR_LAND!U120*AGR_LAND!G117 -> #REF! | AC19: =SUM(AA6:AA19) -> #REF! | AF19: 0.103 | AG19: =AF19*0.95 -> 0.09785
AA20: =O14*AGR_LIV!$U$12*AGR_LIV!$G$5 -> 1458.2067 | AF20: 0.103 | AG20: =AF20*0.95 -> 0.09785
AA21: =O15*AGR_LIV!$U$23*AGR_LIV!$G$16 -> 1175.3398 | AF21: 0 | AG21: =AF21*0.95 -> 0
AA22: =#REF!*AGR_LIV!$U$30*AGR_LIV!$G$27 -> #REF! | AF22: =0.0125 -> 0.0125 | AG22: =AF22*0.95 -> 0.011875
AA23: =O16*AGR_LIV!$U$41*AGR_LIV!$G$34 -> 111.36176 | AF23: 0 | AG23: =AF23*0.95 -> 0
AA24: =#REF!*AGR_LIV!$U$48*AGR_LIV!$G$45 -> #REF! | AC24: suma_liv | AF24: =0.093 -> 0.093 | AG24: =AF24*0.95 -> 0.08835
X25: 0.060318 | Y25: AGR_RESID_CROP_POTATO | AA25: =O17*AGR_LIV!$U$59*AGR_LIV!$G$52 -> 237.54008 | AC25: =SUM(AA20:AA25) -> #REF!
X26: 0.051082 | Y26: AGR_RESID_CROP_STR-HAY
X27: 0.063204 | Y27: AGR_RESID_CROP_OIL | AA27: suma
X28: 0.038672 | Y28: AGR_RESID_CROP_FRUIT | AA28: =SUM(AA6:AA25) -> #REF!
X29: 0.04964 | Y29: AGR_RESID_CROP_VEG
L31: =L32*17695.67 -> 39.82499
L32: =N18*O15 -> 0.00225055
D36: EUR/PLN = | E36: 4.5
D38: Kategoria kosztu | E38: Instalacja średnia (3–8 MW) | F38: Instalacja duża (>14 MW)
D39: CAPEX – część biogazowa [€/kW] | E39: 4300 | F39: 1600
D40: CAPEX – upgrading [€/kW] | E40: 800 | F40: 300
D41: CAPEX – przyłącze i downstream [€/kW] | E41: 270 | F41: 100
D42: OPEX – część biogazowa [€/MWh] | E42: 20 | F42: 20
D43: OPEX – upgrading [€/MWh] | E43: 15 | F43: 10
D44: Gnojowica [€/t] | E44: 2 | F44: 3
D45: Obornik [€/t] | E45: 16 | F45: 13
D46: Odpadów pozbożowe | E46: 10 | F46: 10
...

Sheet AGR_CHP
B2: EC Rolnicze | Combined Heat and Power Plants in Agriculture
E4: ~FI_T: PL
B5: TechName | C5: *TechDesc | D5: Comm-IN | E5: Comm-OUT | F5: Share~2020~2021~FX | G5: Share~2025~FX | H5: Share~2030~FX | I5: Share~2035~FX | J5: Share~2040~FX | K5: Share~2045~FX | L5: Share~2050~FX | M5: Stock~2020~2021 | N5: Stock~2025 | O5: Stock~2030 | P5: Stock~2035 | Q5: Stock~2040 | R5: Stock~2045 | S5: Stock~2050 | T5: EFF | U5: CHPR~FX | V5: CHPR~LO | W5: CHPR~UP | X5: CEH | Y5: BNDACT~2020~2021~UP | Z5: AFA | AA5: AFA~LO | AB5: Cap2Act | AC5: FIXOM | AD5: VAROM
B6: \I: | M6: GW | N6: GW | O6: GW | P6: GW | Q6: GW | R6: GW | S6: GW | T6: % | U6: % | V6: % | W6: % | X6: % | Y6: PJ | Z6: % | AA6: % | AB6: PJ/GW | AC6: zl/kW | AD6: zl/GJ
B7: =AGR_Proc!D22 -> CHPI_EX_BIOG_AGR | C7: =AGR_Proc!E22 -> Industrial Chp Plants for biogas from agriculture residues | D7: =SECTF!E22 -> AGR_BIOG | M7: 0.117868 | N7: 0.117868 | O7: 0.117868 | P7: 0.117868 | Q7: 0.117868 | R7: 0.117868 | S7: 0.117868 | T7: 0.4 | U7: 1 | Z7: 0.81 | AB7: 31.536 | AC7: 125 | AD7: 2.778
E8: =AGR_Comm!D100 -> ELC_GNC
E9: =AGR_Comm!D31 -> AGR_HT_OWN_USE
M12: =M7*AB7*Z7 -> 3.0108391

Sheet DIV
B2: Voltage Dividers
E3: NIEAKTYWNE~FI_T: PL
B5: TechName | C5: * TechDesc | D5: Comm-IN | E5: Comm-OUT | F5: Share-O~UP | G5: EFF
B6: \I: | F6: %
B8: =AGR_Proc!D23 -> ELC_VOLT_DIV_AGR_CHPI | C8: =AGR_Proc!E23 -> Voltage Divider - AGR CHPI | D8: =AGR_Comm!D100 -> ELC_GNC | G8: 1
E9: ELC_HV | F9: 0
E10: ELC_MV | F10: 1
E11: ELC_LV | F11: 0
B14: Heat Dividers
E15: NIEAKTYWNE~~FI_T: PL
B17: TechName | C17: * TechDesc | D17: Comm-IN | E17: Comm-OUT | F17: Share-O~UP | G17: EFF
B18: \I: | F18: %
B19: =AGR_Proc!D24 -> HT_DIV_AGR_CHPI | C19: =AGR_Proc!E24 -> Heat Divider - AGR CHPI | D19: =AGR_Comm!D30 -> HT_AGR_CHPI | G19: 1
E20: =AGR_Comm!D31 -> AGR_HT_OWN_USE | F20: 1
E21: HT_HT_I | F21: 0
E26: ~FI_T:PL
B27: TechName | C27: \I: TechDesc | D27: Comm-IN | E27: Comm-OUT | F27: EFF
B28: \I:
B29: =AGR_Proc!D20 -> AGR_DEM_OWN_HEAT | C29: Industrial Own Heat Consumption | D29: =AGR_Comm!D31 -> AGR_HT_OWN_USE | E29: =AGR_Comm!D92 -> AGR_DEM_HT_OWN_USE | F29: 1

Sheet AGR_FEC
B2: Final energy consumption
E4: ~FI_T: PL
B5: TechName | C5: * TechDesc | D5: Comm-IN | E5: Comm-OUT | F5: Input~2020 | G5: Input~2050
B6: * Technology name | C6: Technology description | D6: Commodity input | E6: Commodity output | F6: Fuel Input per 1 IPI | G6: Fuel Input per 1 IPI | J6: Agriculture Input [PJ] - see sheet ESTAT_2020
B7: =AGR_Proc!D21 -> AGR_DEM_AGR | C7: =AGR_Proc!E21 -> Agriculture Demand Process | D7: =AGR_Comm!D7 -> AGR_HC | F7: =IF(J7<>0,J7/100,"") -> 0.3131203 | G7: 0 | I7: AGR_HC | J7: 31.31203
B8: =IF(J8>0,"","\I:") | D8: =AGR_Comm!D8 -> AGR_BC | F8: =IF(J8<>0,J8/100,"") -> 0.0026657356 | G8: 0 | I8: AGR_BC | J8: 0.26657356
B9: =IF(J9>0,"","\I:") | D9: =AGR_Comm!D9 -> AGR_OIL_GSL | F9: =IF(J9<>0,J9/100,"") -> 0.00045719856 | G9: 0 | I9: AGR_OIL_GSL | J9: 0.045719856
B10: =IF(J10>0,"","\I:") | D10: =AGR_Comm!D10 -> AGR_OIL_DSL | F10: =IF(J10<>0,J10/100,"") -> 0.97438015 | G10: 0 | I10: AGR_OIL_DSL | J10: 97.438015
B11: =IF(J11>0,"","\I:") | D11: =AGR_Comm!D11 -> AGR_OIL_LPG | F11: =IF(J11<>0,J11/100,"") -> 0.028520063 | G11: 0 | I11: AGR_OIL_LPG | J11: 2.8520063
B12: =IF(J12>0,"","\I:") | D12: =AGR_Comm!D12 -> AGR_OIL_FUE | F12: =IF(J12<>0,J12/100,"") -> 0.0040888289 | G12: 0 | I12: AGR_OIL_FUE | J12: 0.40888289
B13: =IF(J13>0,"","\I:") | D13: =AGR_Comm!D13 -> AGR_NAT_GAS | F13: =IF(J13<>0,J13/100,"") -> 0.01805725 | G13: =IF(F17/SUM(F7:F13,F16:F17,F19)>=0.5,SUM(F7:F13,F16,F19),SUM(F7:F13,F16:F17,F19)/2) -> 0.70363612 | I13: AGR_NAT_GAS | J13: 1.805725
B14: =IF(J14>0,"","\I:") | D14: =OLD_AGR_Comm!D14 -> AGR_BIOG | F14: =IF(J14<>0,J14/100,"") -> 0.0037036433 | G14: =F14 -> 0.0037036433 | I14: AGR_BIOG | J14: 0.37036433
B15: =IF(J15>0,"","\I:") | D15: =AGR_Comm!D17 -> AGR_BIOM | F15: =IF(J15<>0,J15/100,"") -> 0.20068044 | G15: =F15 -> 0.20068044 | I15: AGR_BIOM | J15: 20.068044
B16: =IF(J16>0,"","\I:") -> \I: | D16: =AGR_Comm!D18 -> AGR_RDF | F16: =IF(J16<>0,J16/100,"") | I16: AGR_RDF | J16: 0
B17: =IF(J17>0,"","\I:") | D17: =AGR_Comm!D19 -> AGR_ELC | F17: =IF(J17<>0,J17/100,"") -> 0.065982712 | G17: =IF(F17/SUM(F7:F13,F16:F17,F19)>=0.5,F17,SUM(F7:F13,F16:F17,F19)/2) -> 0.70363612 | I17: AGR_ELC | J17: 6.5982712
B18: =IF(J18>0,"","\I:") | D18: =AGR_Comm!D20 -> AGR_DH | F18: =IF(J18<>0,J18/100,"") -> 0.0077501855 | G18: =F18 -> 0.0077501855 | I18: AGR_DH | J18: 0.77501855
B19: =IF(J19>0,"","\I:") -> \I: | D19: =AGR_Comm!D21 -> AGR_OTH_FUE | F19: =IF(J19<>0,J19/100,"") | I19: AGR_OTH_FUE | J19: 0
E20: =AGR_Comm!D22 -> AGR_DEM | J20: =SUM(J7:J19) -> 161.94065

Sheet EMI
B2: Emisje sektorowe | Sectoral emissions
C4: ~PRCCOMEMI: PL
B5: TechName | C5: CommName | D5: AGR_HC | E5: AGR_BC | F5: AGR_OIL_GSL | G5: AGR_OIL_DSL | H5: AGR_OIL_LPG | I5: AGR_OIL_FUE | J5: AGR_NAT_GAS | K5: AGR_BIOG | L5: AGR_BIOM | M5: AGR_RDF | N5: AGR_OTH_FUE
B6: \I: | D6: kt/PJ
B7: =AGR_Proc!$D$21 -> AGR_DEM_AGR | C7: =AGR_Comm!D23 -> AGR_CO2 | D7: 94.19 | E7: 109.08 | F7: 68.61 | G7: 73.33 | H7: 62.44 | I7: 76.59 | J7: 55.82 | K7: 0 | L7: 0 | M7: =D7*0.85 -> 80.0615 | N7: =D7 -> 94.19
B8: =AGR_Proc!$D$21 -> AGR_DEM_AGR | C8: =AGR_Comm!D24 -> AGR_SO2 | D8: 0.5330476 | E8: 0.5330476 | F8: 0.000747851 | G8: 0.000730596 | H8: 4.75959e-05 | I8: 0.000327596 | J8: 4.75959e-05 | K8: 4.75959e-06 | L8: 0.025047596 | M8: 0.025047596 | N8: 0.025047596
B9: =AGR_Proc!$D$21 -> AGR_DEM_AGR | C9: =AGR_Comm!D25 -> AGR_NOX | D9: 0.60670448 | E9: 0.60670448 | F9: 0.88470448 | G9: 0.85470448 | H9: 0.87470448 | I9: 0.50670448 | J9: 0.51470448 | K9: 0.51470448 | L9: 0.54470448 | M9: 0.54470448 | N9: 0.54470448
B10: =AGR_Proc!$D$21 -> AGR_DEM_AGR | C10: =AGR_Comm!D26 -> AGR_TSP | D10: 0.74417388 | E10: 0.74417388 | F10: 0.32875513 | G10: 0.33490388 | H10: 0.32828252 | I10: 0.33037388 | J10: 0.32917388 | K10: 0.32917388 | L10: 1.0489739 | M10: 1.0489739 | N10: 1.0489739
B11: =AGR_Proc!$D$21 -> AGR_DEM_AGR | C11: =AGR_Comm!D27 -> AGR_PM10 | D11: 0.55754892 | E11: 0.55754892 | F11: 0.19233017 | G11: 0.19847892 | H11: 0.19185756 | I11: 0.19394892 | J11: 0.20354892 | K11: 0.20354892 | L11: 0.87654892 | M11: 0.87654892 | N11: 0.87654892
B12: =AGR_Proc!$D$21 -> AGR_DEM_AGR | C12: =AGR_Comm!D28 -> AGR_PM2.5 | D12: 0.35625308 | E12: 0.35625308 | F12: 0.022034333 | G12: 0.028183083 | H12: 0.021561725 | I12: 0.023653083 | J12: 0.022453083 | K12: 0.022453083 | L12: 0.65625308 | M12: 0.65625308 | N12: 0.65625308
B13: \I: | D13: t/PJ
B14: =AGR_Proc!$D$21 -> AGR_DEM_AGR | C14: =AGR_Comm!D29 -> AGR_HG | D14: 0.003 | E14: 0.004 | F14: 6.81293E-05 | G14: 0.00018

Sheet ESTAT_2020
A2: Poland
I4: TOTAL | J4: C0000X0350-0370 | K4: C0110 | L4: C0121 | M4: C0129 | N4: C0210 | O4: C0220 | P4: C0320 | Q4: C0311 | R4: C0312 | S4: C0340 | T4: C0330 | U4: C0350-0370 | V4: C0360 | W4: C0350 | X4: C0371 | Y4: C0379 | Z4: P1000 | AA4: P1100 | AB4: P1200 | AC4: S2000 | AD4: O4000XBIO | AE4: O4100_TOT | AF4: O4200 | AG4: O4300 | AH4: O4400X4410 | AI4: O4500 | AJ4: O4610 | AK4: O4620 | AL4: O4630 | AM4: O4652XR5210B | AN4: O4651 | AO4: O4653 | AP4: O4661XR5230B | AQ4: O4669 | AR4: O4640 | AS4: O4671XR5220B | AT4: O4680 | AU4: O4691 | AV4: O4692 | AW4: O4695 | AX4: O4694 | AY4: O4693 | AZ4: O4699 | BA4: G3000 | BB4: RA000 | BC4: RA100 | BD4: RA500 | BE4: RA300 | BF4: RA420 | BG4: RA410 | BH4: RA200 | BI4: R5110-5150_W6000RI | BJ4: R5160 | BK4: R5300 | BL4: W6210 | BM4: R5210P | BN4: R5210B | BO4: R5220P | BP4: R5220B | BQ4: R5230P | BR4: R5230B | BS4: R5290 | BT4: RA600 | BU4: W6100_6220 | BV4: W6100 | BW4: W6220 | BX4: N900H | BY4: H8000 | BZ4: E7000 | CA4: FE | CB4: BIOE
D5: ktoe | F5: 2020 | I5: Total | J5: Solid fossil fuels | K5: Anthracite | L5: Coking coal | M5: Other bituminous coal | N5: Sub-bituminous coal | O5: Lignite | P5: Patent fuel | Q5: Coke oven coke | R5: Gas coke | S5: Coal tar | T5: Brown coal briquettes | U5: Manufactured gases | V5: Gas works gas | W5: Coke oven gas | X5: Blast furnace gas | Y5: Other recovered gases | Z5: Peat and peat products | AA5: Peat | AB5: Peat products | AC5: Oil shale and oil sands | AD5: Oil and petroleum products | AE5: Crude oil | AF5: Natural gas liquids | AG5: Refinery feedstocks | AH5: Additives and oxygenates (excluding biofuel portion) | AI5: Other hydrocarbons | AJ5: Refinery gas | AK5: Ethane | AL5: Liquefied petroleum gases | AM5: Motor gasoline (excluding biofuel portion) | AN5: Aviation gasoline | AO5: Gasoline-type jet fuel | AP5: Kerosene-type jet fuel (excluding biofuel portion) | AQ5: Other kerosene | AR5: Naphtha | AS5: Gas oil and diesel oil (excluding biofuel portion) | AT5: Fuel oil | AU5: White spirit and special boiling point industrial spirits | AV5: Lubricants | AW5: Bitumen | AX5: Petroleum coke | AY5: Paraffin waxes | AZ5: Other oil products | BA5: Natural gas | BB5: Renewables and biofuels | BC5: Hydro | BD5: Tide, wave, ocean | BE5: Wind | BF5: Solar photovoltaic | BG5: Solar thermal | BH5: Geothermal | BI5: Primary solid biofuels | BJ5: Charcoal | BK5: Biogases | BL5: Renewable municipal waste | BM5: Pure biogasoline | BN5: Blended biogasoline | BO5: Pure biodiesels | BP5: Blended biodiesels | BQ5: Pure bio jet kerosene | BR5: Blended bio jet kerosene | BS5: Other liquid biofuels | BT5: Ambient heat (heat pumps) | BU5: Non-renewable waste | BV5: Industrial waste (non-renewable) | BW5: Non-renewable municipal waste | BX5: Nuclear heat | BY5: Heat | BZ5: Electricity | CA5: Fossil energy | CB5: Bioenergy
